<?xml version="1.0"?>
<robot name="go1">

  <!-- Base link (floating base) -->
  <link name="base">
    <inertial>
      <mass value="0.001"/>
      <origin xyz="0 0 0"/>
      <inertia ixx="1e-6" ixy="0" ixz="0" iyy="1e-6" iyz="0" izz="1e-6"/>
    </inertial>
    <visual>
      <geometry>
        <box size="0.001 0.001 0.001"/>
      </geometry>
    </visual>
  </link>

  <!-- Trunk (main body) -->
  <joint name="floating_base" type="fixed">
    <origin xyz="0 0 0" rpy="0 0 0"/>
    <parent link="base"/>
    <child link="trunk"/>
  </joint>

  <link name="trunk">
    <inertial>
      <origin xyz="0.0223 0.002 -0.0005" rpy="0 0 0"/>
      <mass value="5.204"/>
      <inertia ixx="0.0168128557" ixy="-0.0002296769" ixz="-0.0002945293"
               iyy="0.063009565" iyz="-4.18731e-05" izz="0.0716547275"/>
    </inertial>
    <visual>
      <geometry>
        <box size="0.3762 0.0935 0.114"/>
      </geometry>
    </visual>
    <collision>
      <geometry>
        <box size="0.3762 0.0935 0.114"/>
      </geometry>
    </collision>
  </link>

  <!-- IMU link -->
  <joint name="imu_joint" type="fixed">
    <parent link="trunk"/>
    <child link="imu_link"/>
    <origin xyz="-0.01592 -0.06659 -0.00617" rpy="0 0 0"/>
  </joint>

  <link name="imu_link">
    <inertial>
      <mass value="0.001"/>
      <origin xyz="0 0 0"/>
      <inertia ixx="0.0001" ixy="0" ixz="0" iyy="0.0001" iyz="0" izz="0.0001"/>
    </inertial>
    <visual>
      <geometry>
        <box size="0.001 0.001 0.001"/>
      </geometry>
    </visual>
    <collision>
      <geometry>
        <box size="0.001 0.001 0.001"/>
      </geometry>
    </collision>
  </link>

  <!-- Front Right Leg -->
  <joint name="FR_hip_joint" type="revolute">
    <origin xyz="0.1881 -0.04675 0" rpy="0 0 0"/>
    <parent link="trunk"/>
    <child link="FR_hip"/>
    <axis xyz="1 0 0"/>
    <limit effort="23.7" lower="-0.863" upper="0.863" velocity="30.1"/>
    <dynamics damping="0.0" friction="0.0"/>
  </joint>

  <link name="FR_hip">
    <inertial>
      <origin xyz="-0.005657 0.008752 -0.000102" rpy="0 0 0"/>
      <mass value="0.591"/>
      <inertia ixx="0.000334008405" ixy="1.0826066e-05" ixz="1.290732e-06"
               iyy="0.000619101213" iyz="-1.643194e-06" izz="0.00040057614"/>
    </inertial>
    <visual>
      <origin xyz="0 -0.08 0" rpy="1.5707963267948966 0 0"/>
      <geometry>
        <cylinder length="0.04" radius="0.046"/>
      </geometry>
    </visual>
    <collision>
      <origin xyz="0 -0.08 0" rpy="1.5707963267948966 0 0"/>
      <geometry>
        <cylinder length="0.04" radius="0.046"/>
      </geometry>
    </collision>
  </link>

  <joint name="FR_thigh_joint" type="revolute">
    <origin xyz="0 -0.08 0" rpy="0 0 0"/>
    <parent link="FR_hip"/>
    <child link="FR_thigh"/>
    <axis xyz="0 1 0"/>
    <limit effort="23.7" lower="-0.686" upper="4.501" velocity="30.1"/>
    <dynamics damping="0.0" friction="0.0"/>
  </joint>

  <link name="FR_thigh">
    <inertial>
      <origin xyz="-0.003342 0.018054 -0.033451" rpy="0 0 0"/>
      <mass value="0.92"/>
      <inertia ixx="0.004431760472" ixy="-5.7496807e-05" ixz="-0.000218457134"
               iyy="0.004485671726" iyz="-0.000572001265" izz="0.000740309489"/>
    </inertial>
    <visual>
      <origin xyz="0 0 -0.1065" rpy="0 1.5707963267948966 0"/>
      <geometry>
        <box size="0.15 0.0245 0.034"/>
      </geometry>
    </visual>
    <collision>
      <origin xyz="0 0 -0.1065" rpy="0 1.5707963267948966 0"/>
      <geometry>
        <box size="0.15 0.0245 0.034"/>
      </geometry>
    </collision>
  </link>

  <joint name="FR_calf_joint" type="revolute">
    <origin xyz="0 0 -0.213" rpy="0 0 0"/>
    <parent link="FR_thigh"/>
    <child link="FR_calf"/>
    <axis xyz="0 1 0"/>
    <limit effort="35.55" lower="-2.818" upper="-0.888" velocity="20.06"/>
    <dynamics damping="0.0" friction="0.0"/>
  </joint>

  <link name="FR_calf">
    <inertial>
      <origin xyz="0.006197 0.001408 -0.116695" rpy="0 0 0"/>
      <mass value="0.135862"/>
      <inertia ixx="0.001088793059" ixy="-2.55679e-07" ixz="7.117814e-06"
               iyy="0.001100428748" iyz="2.077264e-06" izz="2.4787446e-05"/>
    </inertial>
    <visual>
      <origin xyz="0 0 -0.1065" rpy="0 1.5707963267948966 0"/>
      <geometry>
        <box size="0.213 0.016 0.016"/>
      </geometry>
    </visual>
    <collision>
      <origin xyz="0 0 -0.1065" rpy="0 1.5707963267948966 0"/>
      <geometry>
        <box size="0.213 0.016 0.016"/>
      </geometry>
    </collision>
  </link>

  <joint name="FR_foot_fixed" type="fixed" dont_collapse="true">
    <origin xyz="0 0 -0.213" rpy="0 0 0"/>
    <parent link="FR_calf"/>
    <child link="FR_foot"/>
  </joint>

  <link name="FR_foot">
    <inertial>
      <mass value="0.06"/>
      <inertia ixx="9.6e-06" ixy="0.0" ixz="0.0" iyy="9.6e-06" iyz="0.0" izz="9.6e-06"/>
    </inertial>
    <visual>
      <geometry>
        <sphere radius="0.01"/>
      </geometry>
    </visual>
    <collision>
      <geometry>
        <sphere radius="0.02"/>
      </geometry>
    </collision>
  </link>

  <!-- Front Left Leg -->
  <joint name="FL_hip_joint" type="revolute">
    <origin xyz="0.1881 0.04675 0" rpy="0 0 0"/>
    <parent link="trunk"/>
    <child link="FL_hip"/>
    <axis xyz="1 0 0"/>
    <limit effort="23.7" lower="-0.863" upper="0.863" velocity="30.1"/>
    <dynamics damping="0.0" friction="0.0"/>
  </joint>

  <link name="FL_hip">
    <inertial>
      <origin xyz="-0.005657 -0.008752 -0.000102" rpy="0 0 0"/>
      <mass value="0.591"/>
      <inertia ixx="0.000334008405" ixy="-1.0826066e-05" ixz="1.290732e-06"
               iyy="0.000619101213" iyz="1.643194e-06" izz="0.00040057614"/>
    </inertial>
    <visual>
      <origin xyz="0 0.08 0" rpy="1.5707963267948966 0 0"/>
      <geometry>
        <cylinder length="0.04" radius="0.046"/>
      </geometry>
    </visual>
    <collision>
      <origin xyz="0 0.08 0" rpy="1.5707963267948966 0 0"/>
      <geometry>
        <cylinder length="0.04" radius="0.046"/>
      </geometry>
    </collision>
  </link>

  <joint name="FL_thigh_joint" type="revolute">
    <origin xyz="0 0.08 0" rpy="0 0 0"/>
    <parent link="FL_hip"/>
    <child link="FL_thigh"/>
    <axis xyz="0 1 0"/>
    <limit effort="23.7" lower="-0.686" upper="4.501" velocity="30.1"/>
    <dynamics damping="0.0" friction="0.0"/>
  </joint>

  <link name="FL_thigh">
    <inertial>
      <origin xyz="-0.003342 -0.018054 -0.033451" rpy="0 0 0"/>
      <mass value="0.92"/>
      <inertia ixx="0.004431760472" ixy="5.7496807e-05" ixz="-0.000218457134"
               iyy="0.004485671726" iyz="0.000572001265" izz="0.000740309489"/>
    </inertial>
    <visual>
      <origin xyz="0 0 -0.1065" rpy="0 1.5707963267948966 0"/>
      <geometry>
        <box size="0.15 0.0245 0.034"/>
      </geometry>
    </visual>
    <collision>
      <origin xyz="0 0 -0.1065" rpy="0 1.5707963267948966 0"/>
      <geometry>
        <box size="0.15 0.0245 0.034"/>
      </geometry>
    </collision>
  </link>

  <joint name="FL_calf_joint" type="revolute">
    <origin xyz="0 0 -0.213" rpy="0 0 0"/>
    <parent link="FL_thigh"/>
    <child link="FL_calf"/>
    <axis xyz="0 1 0"/>
    <limit effort="35.55" lower="-2.818" upper="-0.888" velocity="20.06"/>
    <dynamics damping="0.0" friction="0.0"/>
  </joint>

  <link name="FL_calf">
    <inertial>
      <origin xyz="0.006197 0.001408 -0.116695" rpy="0 0 0"/>
      <mass value="0.135862"/>
      <inertia ixx="0.001088793059" ixy="-2.55679e-07" ixz="7.117814e-06"
               iyy="0.001100428748" iyz="2.077264e-06" izz="2.4787446e-05"/>
    </inertial>
    <visual>
      <origin xyz="0 0 -0.1065" rpy="0 1.5707963267948966 0"/>
      <geometry>
        <box size="0.213 0.016 0.016"/>
      </geometry>
    </visual>
    <collision>
      <origin xyz="0 0 -0.1065" rpy="0 1.5707963267948966 0"/>
      <geometry>
        <box size="0.213 0.016 0.016"/>
      </geometry>
    </collision>
  </link>

  <joint name="FL_foot_fixed" type="fixed" dont_collapse="true">
    <origin xyz="0 0 -0.213" rpy="0 0 0"/>
    <parent link="FL_calf"/>
    <child link="FL_foot"/>
  </joint>

  <link name="FL_foot">
    <inertial>
      <mass value="0.06"/>
      <inertia ixx="9.6e-06" ixy="0.0" ixz="0.0" iyy="9.6e-06" iyz="0.0" izz="9.6e-06"/>
    </inertial>
    <visual>
      <geometry>
        <sphere radius="0.01"/>
      </geometry>
    </visual>
    <collision>
      <geometry>
        <sphere radius="0.02"/>
      </geometry>
    </collision>
  </link>

  <!-- Rear Right Leg -->
  <joint name="RR_hip_joint" type="revolute">
    <origin xyz="-0.1881 -0.04675 0" rpy="0 0 0"/>
    <parent link="trunk"/>
    <child link="RR_hip"/>
    <axis xyz="1 0 0"/>
    <limit effort="23.7" lower="-0.863" upper="0.863" velocity="30.1"/>
    <dynamics damping="0.0" friction="0.0"/>
  </joint>

  <link name="RR_hip">
    <inertial>
      <origin xyz="0.005657 0.008752 -0.000102" rpy="0 0 0"/>
      <mass value="0.591"/>
      <inertia ixx="0.000334008405" ixy="-1.0826066e-05" ixz="-1.290732e-06"
               iyy="0.000619101213" iyz="-1.643194e-06" izz="0.00040057614"/>
    </inertial>
    <visual>
      <origin xyz="0 -0.08 0" rpy="1.5707963267948966 0 0"/>
      <geometry>
        <cylinder length="0.04" radius="0.046"/>
      </geometry>
    </visual>
    <collision>
      <origin xyz="0 -0.08 0" rpy="1.5707963267948966 0 0"/>
      <geometry>
        <cylinder length="0.04" radius="0.046"/>
      </geometry>
    </collision>
  </link>

  <joint name="RR_thigh_joint" type="revolute">
    <origin xyz="0 -0.08 0" rpy="0 0 0"/>
    <parent link="RR_hip"/>
    <child link="RR_thigh"/>
    <axis xyz="0 1 0"/>
    <limit effort="23.7" lower="-0.686" upper="4.501" velocity="30.1"/>
    <dynamics damping="0.0" friction="0.0"/>
  </joint>

  <link name="RR_thigh">
    <inertial>
      <origin xyz="-0.003342 0.018054 -0.033451" rpy="0 0 0"/>
      <mass value="0.92"/>
      <inertia ixx="0.004431760472" ixy="-5.7496807e-05" ixz="-0.000218457134"
               iyy="0.004485671726" iyz="-0.000572001265" izz="0.000740309489"/>
    </inertial>
    <visual>
      <origin xyz="0 0 -0.1065" rpy="0 1.5707963267948966 0"/>
      <geometry>
        <box size="0.15 0.0245 0.034"/>
      </geometry>
    </visual>
    <collision>
      <origin xyz="0 0 -0.1065" rpy="0 1.5707963267948966 0"/>
      <geometry>
        <box size="0.15 0.0245 0.034"/>
      </geometry>
    </collision>
  </link>

  <joint name="RR_calf_joint" type="revolute">
    <origin xyz="0 0 -0.213" rpy="0 0 0"/>
    <parent link="RR_thigh"/>
    <child link="RR_calf"/>
    <axis xyz="0 1 0"/>
    <limit effort="35.55" lower="-2.818" upper="-0.888" velocity="20.06"/>
    <dynamics damping="0.0" friction="0.0"/>
  </joint>

  <link name="RR_calf">
    <inertial>
      <origin xyz="0.006197 0.001408 -0.116695" rpy="0 0 0"/>
      <mass value="0.135862"/>
      <inertia ixx="0.001088793059" ixy="-2.55679e-07" ixz="7.117814e-06"
               iyy="0.001100428748" iyz="2.077264e-06" izz="2.4787446e-05"/>
    </inertial>
    <visual>
      <origin xyz="0 0 -0.1065" rpy="0 1.5707963267948966 0"/>
      <geometry>
        <box size="0.213 0.016 0.016"/>
      </geometry>
    </visual>
    <collision>
      <origin xyz="0 0 -0.1065" rpy="0 1.5707963267948966 0"/>
      <geometry>
        <box size="0.213 0.016 0.016"/>
      </geometry>
    </collision>
  </link>

  <joint name="RR_foot_fixed" type="fixed" dont_collapse="true">
    <origin xyz="0 0 -0.213" rpy="0 0 0"/>
    <parent link="RR_calf"/>
    <child link="RR_foot"/>
  </joint>

  <link name="RR_foot">
    <inertial>
      <mass value="0.06"/>
      <inertia ixx="9.6e-06" ixy="0.0" ixz="0.0" iyy="9.6e-06" iyz="0.0" izz="9.6e-06"/>
    </inertial>
    <visual>
      <geometry>
        <sphere radius="0.01"/>
      </geometry>
    </visual>
    <collision>
      <geometry>
        <sphere radius="0.02"/>
      </geometry>
    </collision>
  </link>

  <!-- Rear Left Leg -->
  <joint name="RL_hip_joint" type="revolute">
    <origin xyz="-0.1881 0.04675 0" rpy="0 0 0"/>
    <parent link="trunk"/>
    <child link="RL_hip"/>
    <axis xyz="1 0 0"/>
    <limit effort="23.7" lower="-0.863" upper="0.863" velocity="30.1"/>
    <dynamics damping="0.0" friction="0.0"/>
  </joint>

  <link name="RL_hip">
    <inertial>
      <origin xyz="0.005657 -0.008752 -0.000102" rpy="0 0 0"/>
      <mass value="0.591"/>
      <inertia ixx="0.000334008405" ixy="1.0826066e-05" ixz="-1.290732e-06"
               iyy="0.000619101213" iyz="1.643194e-06" izz="0.00040057614"/>
    </inertial>
    <visual>
      <origin xyz="0 0.08 0" rpy="1.5707963267948966 0 0"/>
      <geometry>
        <cylinder length="0.04" radius="0.046"/>
      </geometry>
    </visual>
    <collision>
      <origin xyz="0 0.08 0" rpy="1.5707963267948966 0 0"/>
      <geometry>
        <cylinder length="0.04" radius="0.046"/>
      </geometry>
    </collision>
  </link>

  <joint name="RL_thigh_joint" type="revolute">
    <origin xyz="0 0.08 0" rpy="0 0 0"/>
    <parent link="RL_hip"/>
    <child link="RL_thigh"/>
    <axis xyz="0 1 0"/>
    <limit effort="23.7" lower="-0.686" upper="4.501" velocity="30.1"/>
    <dynamics damping="0.0" friction="0.0"/>
  </joint>

  <link name="RL_thigh">
    <inertial>
      <origin xyz="-0.003342 -0.018054 -0.033451" rpy="0 0 0"/>
      <mass value="0.92"/>
      <inertia ixx="0.004431760472" ixy="5.7496807e-05" ixz="-0.000218457134"
               iyy="0.004485671726" iyz="0.000572001265" izz="0.000740309489"/>
    </inertial>
    <visual>
      <origin xyz="0 0 -0.1065" rpy="0 1.5707963267948966 0"/>
      <geometry>
        <box size="0.15 0.0245 0.034"/>
      </geometry>
    </visual>
    <collision>
      <origin xyz="0 0 -0.1065" rpy="0 1.5707963267948966 0"/>
      <geometry>
        <box size="0.15 0.0245 0.034"/>
      </geometry>
    </collision>
  </link>

  <joint name="RL_calf_joint" type="revolute">
    <origin xyz="0 0 -0.213" rpy="0 0 0"/>
    <parent link="RL_thigh"/>
    <child link="RL_calf"/>
    <axis xyz="0 1 0"/>
    <limit effort="35.55" lower="-2.818" upper="-0.888" velocity="20.06"/>
    <dynamics damping="0.0" friction="0.0"/>
  </joint>

  <link name="RL_calf">
    <inertial>
      <origin xyz="0.006197 0.001408 -0.116695" rpy="0 0 0"/>
      <mass value="0.135862"/>
      <inertia ixx="0.001088793059" ixy="-2.55679e-07" ixz="7.117814e-06"
               iyy="0.001100428748" iyz="2.077264e-06" izz="2.4787446e-05"/>
    </inertial>
    <visual>
      <origin xyz="0 0 -0.1065" rpy="0 1.5707963267948966 0"/>
      <geometry>
        <box size="0.213 0.016 0.016"/>
      </geometry>
    </visual>
    <collision>
      <origin xyz="0 0 -0.1065" rpy="0 1.5707963267948966 0"/>
      <geometry>
        <box size="0.213 0.016 0.016"/>
      </geometry>
    </collision>
  </link>

  <joint name="RL_foot_fixed" type="fixed" dont_collapse="true">
    <origin xyz="0 0 -0.213" rpy="0 0 0"/>
    <parent link="RL_calf"/>
    <child link="RL_foot"/>
  </joint>

  <link name="RL_foot">
    <inertial>
      <mass value="0.06"/>
      <inertia ixx="9.6e-06" ixy="0.0" ixz="0.0" iyy="9.6e-06" iyz="0.0" izz="9.6e-06"/>
    </inertial>
    <visual>
      <geometry>
        <sphere radius="0.01"/>
      </geometry>
    </visual>
    <collision>
      <geometry>
        <sphere radius="0.02"/>
      </geometry>
    </collision>
  </link>

</robot>